[2024-11-10T08:17:42.158+0000] {local_task_job_runner.py:123} INFO - ::group::Pre task execution logs
[2024-11-10T08:17:42.190+0000] {taskinstance.py:2613} INFO - Dependencies all met for dep_context=non-requeueable deps ti=<TaskInstance: daily_news_crawler.fetch_news_data manual__2024-11-10T08:17:04.594918+00:00 [queued]>
[2024-11-10T08:17:42.205+0000] {taskinstance.py:2613} INFO - Dependencies all met for dep_context=requeueable deps ti=<TaskInstance: daily_news_crawler.fetch_news_data manual__2024-11-10T08:17:04.594918+00:00 [queued]>
[2024-11-10T08:17:42.206+0000] {taskinstance.py:2866} INFO - Starting attempt 1 of 2
[2024-11-10T08:17:42.235+0000] {taskinstance.py:2889} INFO - Executing <Task(PythonOperator): fetch_news_data> on 2024-11-10 08:17:04.594918+00:00
[2024-11-10T08:17:42.251+0000] {warnings.py:112} WARNING - /home/***/.local/lib/python3.12/site-packages/***/task/task_runner/standard_task_runner.py:70: DeprecationWarning: This process (pid=103) is multi-threaded, use of fork() may lead to deadlocks in the child.
  pid = os.fork()

[2024-11-10T08:17:42.255+0000] {standard_task_runner.py:72} INFO - Started process 105 to run task
[2024-11-10T08:17:42.255+0000] {standard_task_runner.py:104} INFO - Running: ['***', 'tasks', 'run', 'daily_news_crawler', 'fetch_news_data', 'manual__2024-11-10T08:17:04.594918+00:00', '--job-id', '17', '--raw', '--subdir', 'DAGS_FOLDER/nh_news_crawling.py', '--cfg-path', '/tmp/tmp03ak6rs2']
[2024-11-10T08:17:42.257+0000] {standard_task_runner.py:105} INFO - Job 17: Subtask fetch_news_data
[2024-11-10T08:17:42.356+0000] {task_command.py:467} INFO - Running <TaskInstance: daily_news_crawler.fetch_news_data manual__2024-11-10T08:17:04.594918+00:00 [running]> on host f0351efcc7d8
[2024-11-10T08:17:42.915+0000] {taskinstance.py:3132} INFO - Exporting env vars: AIRFLOW_CTX_DAG_OWNER='***' AIRFLOW_CTX_DAG_ID='daily_news_crawler' AIRFLOW_CTX_TASK_ID='fetch_news_data' AIRFLOW_CTX_EXECUTION_DATE='2024-11-10T08:17:04.594918+00:00' AIRFLOW_CTX_TRY_NUMBER='1' AIRFLOW_CTX_DAG_RUN_ID='manual__2024-11-10T08:17:04.594918+00:00'
[2024-11-10T08:17:42.928+0000] {logging_mixin.py:190} INFO - Task instance is in running state
[2024-11-10T08:17:42.955+0000] {logging_mixin.py:190} INFO -  Previous state of the Task instance: queued
[2024-11-10T08:17:42.960+0000] {logging_mixin.py:190} INFO - Current task name:fetch_news_data state:running start_date:2024-11-10 08:17:42.191238+00:00
[2024-11-10T08:17:42.964+0000] {logging_mixin.py:190} INFO - Dag name:daily_news_crawler and current dag run status:running
[2024-11-10T08:17:42.976+0000] {taskinstance.py:731} INFO - ::endgroup::
[2024-11-10T08:17:50.591+0000] {logging_mixin.py:190} INFO - Error saving to database: ('42000', "[42000] [Microsoft][ODBC Driver 18 for SQL Server][SQL Server]Cannot open server 'jy-nh-server01' requested by the login. Client with IP address '121.64.9.44' is not allowed to access the server.  To enable access, use the Azure Management Portal or run sp_set_firewall_rule on the master database to create a firewall rule for this IP address or address range.  It may take up to five minutes for this change to take effect. (40615) (SQLDriverConnect)")
[2024-11-10T08:17:50.600+0000] {taskinstance.py:3311} ERROR - Task failed with exception
Traceback (most recent call last):
  File "/home/airflow/.local/lib/python3.12/site-packages/airflow/models/taskinstance.py", line 767, in _execute_task
    result = _execute_callable(context=context, **execute_callable_kwargs)
             ^^^^^^^^^^^^^^^^^^^^^^^^^^^^^^^^^^^^^^^^^^^^^^^^^^^^^^^^^^^^^
  File "/home/airflow/.local/lib/python3.12/site-packages/airflow/models/taskinstance.py", line 733, in _execute_callable
    return ExecutionCallableRunner(
           ^^^^^^^^^^^^^^^^^^^^^^^^
  File "/home/airflow/.local/lib/python3.12/site-packages/airflow/utils/operator_helpers.py", line 252, in run
    return self.func(*args, **kwargs)
           ^^^^^^^^^^^^^^^^^^^^^^^^^^
  File "/home/airflow/.local/lib/python3.12/site-packages/airflow/models/baseoperator.py", line 417, in wrapper
    return func(self, *args, **kwargs)
           ^^^^^^^^^^^^^^^^^^^^^^^^^^^
  File "/home/airflow/.local/lib/python3.12/site-packages/airflow/operators/python.py", line 238, in execute
    return_value = self.execute_callable()
                   ^^^^^^^^^^^^^^^^^^^^^^^
  File "/home/airflow/.local/lib/python3.12/site-packages/airflow/operators/python.py", line 256, in execute_callable
    return runner.run(*self.op_args, **self.op_kwargs)
           ^^^^^^^^^^^^^^^^^^^^^^^^^^^^^^^^^^^^^^^^^^^
  File "/home/airflow/.local/lib/python3.12/site-packages/airflow/utils/operator_helpers.py", line 252, in run
    return self.func(*args, **kwargs)
           ^^^^^^^^^^^^^^^^^^^^^^^^^^
  File "/opt/airflow/dags/nh_news_crawling.py", line 64, in fetch_news_data
    cursor.close()
    ^^^^^^
UnboundLocalError: cannot access local variable 'cursor' where it is not associated with a value
[2024-11-10T08:17:50.938+0000] {logging_mixin.py:190} INFO - Task instance in failure state
[2024-11-10T08:17:50.947+0000] {logging_mixin.py:190} INFO - Task start:2024-11-10 08:17:42.191238+00:00 end:2024-11-10 08:17:50.932102+00:00 duration:8.740864
[2024-11-10T08:17:50.975+0000] {logging_mixin.py:190} INFO - Task:<Task(PythonOperator): fetch_news_data> dag:<DAG: daily_news_crawler> dagrun:<DagRun daily_news_crawler @ 2024-11-10 08:17:04.594918+00:00: manual__2024-11-10T08:17:04.594918+00:00, state:running, queued_at: 2024-11-10 08:17:04.784789+00:00. externally triggered: True>
[2024-11-10T08:17:50.990+0000] {logging_mixin.py:190} INFO - Failure caused by cannot access local variable 'cursor' where it is not associated with a value
[2024-11-10T08:17:50.992+0000] {taskinstance.py:1225} INFO - Marking task as UP_FOR_RETRY. dag_id=daily_news_crawler, task_id=fetch_news_data, run_id=manual__2024-11-10T08:17:04.594918+00:00, execution_date=20241110T081704, start_date=20241110T081742, end_date=20241110T081750
[2024-11-10T08:17:51.123+0000] {taskinstance.py:340} INFO - ::group::Post task execution logs
[2024-11-10T08:17:51.131+0000] {standard_task_runner.py:124} ERROR - Failed to execute job 17 for task fetch_news_data (cannot access local variable 'cursor' where it is not associated with a value; 105)
Traceback (most recent call last):
  File "/home/airflow/.local/lib/python3.12/site-packages/airflow/task/task_runner/standard_task_runner.py", line 117, in _start_by_fork
    ret = args.func(args, dag=self.dag)
          ^^^^^^^^^^^^^^^^^^^^^^^^^^^^^
  File "/home/airflow/.local/lib/python3.12/site-packages/airflow/cli/cli_config.py", line 49, in command
    return func(*args, **kwargs)
           ^^^^^^^^^^^^^^^^^^^^^
  File "/home/airflow/.local/lib/python3.12/site-packages/airflow/utils/cli.py", line 116, in wrapper
    return f(*args, **kwargs)
           ^^^^^^^^^^^^^^^^^^
  File "/home/airflow/.local/lib/python3.12/site-packages/airflow/cli/commands/task_command.py", line 483, in task_run
    task_return_code = _run_task_by_selected_method(args, _dag, ti)
                       ^^^^^^^^^^^^^^^^^^^^^^^^^^^^^^^^^^^^^^^^^^^^
  File "/home/airflow/.local/lib/python3.12/site-packages/airflow/cli/commands/task_command.py", line 256, in _run_task_by_selected_method
    return _run_raw_task(args, ti)
           ^^^^^^^^^^^^^^^^^^^^^^^
  File "/home/airflow/.local/lib/python3.12/site-packages/airflow/cli/commands/task_command.py", line 341, in _run_raw_task
    return ti._run_raw_task(
           ^^^^^^^^^^^^^^^^^
  File "/home/airflow/.local/lib/python3.12/site-packages/airflow/utils/session.py", line 97, in wrapper
    return func(*args, session=session, **kwargs)
           ^^^^^^^^^^^^^^^^^^^^^^^^^^^^^^^^^^^^^^
  File "/home/airflow/.local/lib/python3.12/site-packages/airflow/models/taskinstance.py", line 3005, in _run_raw_task
    return _run_raw_task(
           ^^^^^^^^^^^^^^
  File "/home/airflow/.local/lib/python3.12/site-packages/airflow/models/taskinstance.py", line 273, in _run_raw_task
    TaskInstance._execute_task_with_callbacks(
  File "/home/airflow/.local/lib/python3.12/site-packages/airflow/models/taskinstance.py", line 3159, in _execute_task_with_callbacks
    result = self._execute_task(context, task_orig)
             ^^^^^^^^^^^^^^^^^^^^^^^^^^^^^^^^^^^^^^
  File "/home/airflow/.local/lib/python3.12/site-packages/airflow/models/taskinstance.py", line 3183, in _execute_task
    return _execute_task(self, context, task_orig)
           ^^^^^^^^^^^^^^^^^^^^^^^^^^^^^^^^^^^^^^^
  File "/home/airflow/.local/lib/python3.12/site-packages/airflow/models/taskinstance.py", line 767, in _execute_task
    result = _execute_callable(context=context, **execute_callable_kwargs)
             ^^^^^^^^^^^^^^^^^^^^^^^^^^^^^^^^^^^^^^^^^^^^^^^^^^^^^^^^^^^^^
  File "/home/airflow/.local/lib/python3.12/site-packages/airflow/models/taskinstance.py", line 733, in _execute_callable
    return ExecutionCallableRunner(
           ^^^^^^^^^^^^^^^^^^^^^^^^
  File "/home/airflow/.local/lib/python3.12/site-packages/airflow/utils/operator_helpers.py", line 252, in run
    return self.func(*args, **kwargs)
           ^^^^^^^^^^^^^^^^^^^^^^^^^^
  File "/home/airflow/.local/lib/python3.12/site-packages/airflow/models/baseoperator.py", line 417, in wrapper
    return func(self, *args, **kwargs)
           ^^^^^^^^^^^^^^^^^^^^^^^^^^^
  File "/home/airflow/.local/lib/python3.12/site-packages/airflow/operators/python.py", line 238, in execute
    return_value = self.execute_callable()
                   ^^^^^^^^^^^^^^^^^^^^^^^
  File "/home/airflow/.local/lib/python3.12/site-packages/airflow/operators/python.py", line 256, in execute_callable
    return runner.run(*self.op_args, **self.op_kwargs)
           ^^^^^^^^^^^^^^^^^^^^^^^^^^^^^^^^^^^^^^^^^^^
  File "/home/airflow/.local/lib/python3.12/site-packages/airflow/utils/operator_helpers.py", line 252, in run
    return self.func(*args, **kwargs)
           ^^^^^^^^^^^^^^^^^^^^^^^^^^
  File "/opt/airflow/dags/nh_news_crawling.py", line 64, in fetch_news_data
    cursor.close()
    ^^^^^^
UnboundLocalError: cannot access local variable 'cursor' where it is not associated with a value
[2024-11-10T08:17:51.291+0000] {local_task_job_runner.py:266} INFO - Task exited with return code 1
[2024-11-10T08:17:51.367+0000] {taskinstance.py:3895} INFO - 0 downstream tasks scheduled from follow-on schedule check
[2024-11-10T08:17:51.371+0000] {local_task_job_runner.py:245} INFO - ::endgroup::
